<?xml version="1.0"?>
<robot xmlns:xacro="http://ros.org/wiki/xacro">
    <!-- Define robot constants -->
    <xacro:property name="base_width" value="0.31"/>
    <xacro:property name="base_length" value="0.42"/>
    <xacro:property name="base_height" value="0.18"/>

    <xacro:property name="wheel_radius" value="0.10"/>
    <xacro:property name="wheel_width" value="0.04"/>
    <xacro:property name="wheel_ygap" value="0.025"/>
    <xacro:property name="wheel_zoff" value="0.05"/>
    <xacro:property name="wheel_xoff" value="0.12"/>

    <xacro:property name="caster_xoff" value="0.14"/>

    <!-- Define some commonly used intertial properties  -->
    <xacro:macro name="box_inertia" params="m w h d">
        <inertial>
            <origin xyz="0 0 0" rpy="${pi/2} 0 ${pi/2}"/>
            <mass value="${m}"/>
            <inertia ixx="${(m/12) * (h*h + d*d)}" ixy="0.0" ixz="0.0" iyy="${(m/12) * (w*w + d*d)}" iyz="0.0" izz="${(m/12) * (w*w + h*h)}"/>
        </inertial>
    </xacro:macro>

    <xacro:macro name="cylinder_inertia" params="m r h">
        <inertial>
            <origin xyz="0 0 0" rpy="${pi/2} 0 0" />
            <mass value="${m}"/>
            <inertia ixx="${(m/12) * (3*r*r + h*h)}" ixy = "0" ixz = "0" iyy="${(m/12) * (3*r*r + h*h)}" iyz = "0" izz="${(m/2) * (r*r)}"/>
        </inertial>
    </xacro:macro>

    <xacro:macro name="sphere_inertia" params="m r">
        <inertial>
            <mass value="${m}"/>
            <inertia ixx="${(2/5) * m * (r*r)}" ixy="0.0" ixz="0.0" iyy="${(2/5) * m * (r*r)}" iyz="0.0" izz="${(2/5) * m * (r*r)}"/>
        </inertial>
    </xacro:macro>
        <!-- Wheels -->
    <xacro:macro name="wheel" params="prefix x_reflect y_reflect">
        <link name="${prefix}_link">
            <visual>
                <origin xyz="0 0 0" rpy="${pi/2} 0 0"/>
                <geometry>
                    <cylinder radius="${wheel_radius}" length="${wheel_width}"/>
                </geometry>
                <material name="Red">
                    <color rgba="1 0.0 0.1 1.0"/>
                </material>
            </visual>

            <collision>
                <origin xyz="0 0 0" rpy="${pi/2} 0 0"/>
                <geometry>
                    <cylinder radius="${wheel_radius}" length="${wheel_width}"/>
                </geometry>
            </collision>
            <xacro:cylinder_inertia m="0.5" r="${wheel_radius}" h="${wheel_width}"/>
        </link>

        <gazebo reference="${prefix}_link">
            <surface>
                <friction>
                    <ode>
                        <mu>1</mu>
                        <mu2>1</mu2>
                        <slip1>0.035</slip1>
                        <slip2>0</slip2>
                        <fdir1>0 0 1</fdir1>
                    </ode>
                    <bullet>
                        <friction>1</friction>
                        <friction2>1</friction2>
                        <rolling_friction>0.1</rolling_friction>
                        <spinning_friction>0.1</spinning_friction>
                    </bullet>
                </friction>
            </surface>
        </gazebo>

        <joint name="${prefix}_joint" type="continuous">
            <parent link="base_link"/>
            <child link="${prefix}_link"/>
            <origin xyz="${x_reflect*wheel_xoff} ${y_reflect*(base_width/2+wheel_ygap)} ${-wheel_zoff}" rpy="0 0 0"/>
            <axis xyz="0 1 0"/>
        </joint>
    </xacro:macro>
</robot>